Traceback (most recent call last):
  File "/scratch/eb162/venv/lib/python3.7/site-packages/scipy/io/matlab/mio.py", line 39, in _open_file
    return open(file_like, mode), True
FileNotFoundError: [Errno 2] No such file or directory: '319_gam_preproc_neu123_ACAv_CSP011_2020-07-28_010.mat'

During handling of the above exception, another exception occurred:

Traceback (most recent call last):
  File "/scratch/eb162/GAM_Repo/JP/fit_dataset_auto.py", line 55, in <module>
    gam_raw_inputs, counts, trial_idx, info_dict, var_names = parse_fun(table['path_file'][job_id])
  File "/scratch/eb162/GAM_Repo/JP/fit_dataset_auto.py", line 47, in <lambda>
    parse_fun = lambda path_remote: parse_mat_remote(path_remote, local_path, job_id, neuron_id)
  File "/scratch/eb162/GAM_Repo/JP/parsing_tools.py", line 88, in parse_mat_remote
    dat = loadmat(fhname)
  File "/scratch/eb162/venv/lib/python3.7/site-packages/scipy/io/matlab/mio.py", line 224, in loadmat
    with _open_file_context(file_name, appendmat) as f:
  File "/share/apps/anaconda3/2020.02/lib/python3.7/contextlib.py", line 112, in __enter__
    return next(self.gen)
  File "/scratch/eb162/venv/lib/python3.7/site-packages/scipy/io/matlab/mio.py", line 17, in _open_file_context
    f, opened = _open_file(file_like, appendmat, mode)
  File "/scratch/eb162/venv/lib/python3.7/site-packages/scipy/io/matlab/mio.py", line 45, in _open_file
    return open(file_like, mode), True
FileNotFoundError: [Errno 2] No such file or directory: '319_gam_preproc_neu123_ACAv_CSP011_2020-07-28_010.mat'
